Workbook

Sheet User Stories
A1: Story | B1: Module | C1: Role | D1: As a... | E1: I want to... | F1: So that... | G1: Acceptance Criteria | H1: Priority | I1: Milestone | J1: Comments | K1: Status
A2: US-001 | B2: Account | C2: User | D2: New user | E2: register with my email and password | F2: I can create a personal account | G2: • Valid details create a user account • Duplicate email and invalid inputs are rejected • Password is stored securely | H2: Must Have | I2: M0 — Foundation | J2: Implemented by registration validation, ASP.NET Core Identity and confirmation-email dispatch. | K2: In Progress
A3: US-002 | B3: Account | C3: User | D3: Registered user | E3: confirm my email address | F3: my account email is verified | G3: • Confirmation token is validated • Valid token confirms the email • Invalid or expired token returns a clear error | H3: Must Have | I3: M0 — Foundation | J3: Implemented by GET /api/auth/confirm-email and Identity email tokens. | K3: In Progress
A4: US-003 | B4: Account | C4: User | D4: Registered user | E4: log in to my account | F4: I can access my libraries securely | G4: • Valid credentials return authentication tokens • Invalid credentials do not authenticate • Protected endpoints require authentication | H4: Must Have | I4: M0 — Foundation | J4: Implemented by POST /api/auth/login, JWT issuance and protected controllers. | K4: In Progress
A5: US-004 | B5: Account | C5: User | D5: Authenticated user | E5: refresh an expired access token | F5: I can continue using the app without repeatedly logging in | G5: • Valid refresh token issues new authentication tokens • Expired or revoked refresh token is rejected • Refresh token rotation or revocation is enforced | H5: Must Have | I5: M0 — Foundation | J5: Implemented by POST /api/auth/refresh with refresh-token rotation and revocation. | K5: In Progress
A6: US-005 | B6: Account | C6: User | D6: Registered user | E6: request a new email-confirmation message | F6: I can finish verification when the original message is unavailable | G6: • An unconfirmed account receives a new confirmation challenge • Confirmed and unknown accounts do not reveal account state • The endpoint returns a safe, consistent response | H6: Must Have | I6: M0 — Foundation | J6: Implemented by POST /api/auth/resend-confirmation and AuthService. | K6: In Progress
A7: US-006 | B7: Account | C7: User | D7: Authenticated user | E7: log out of my current refresh-token session | F7: a lost token cannot keep creating access tokens | G7: • Logout requires an authenticated user • The supplied refresh-token session is revoked • A revoked refresh token cannot be used again | H7: Must Have | I7: M0 — Foundation | J7: Implemented by POST /api/auth/logout with refresh-session revocation. | K7: In Progress
A8: US-007 | B8: API platform | C8: Developer | D8: API client developer | E8: receive consistent success and failure responses | F8: the client can handle API outcomes predictably | G8: • Successful responses use the common API envelope • Validation errors include field-level details • Authentication, authorization and not-found failures use stable codes and a trace identifier | H8: Should Have | I8: M0 — Foundation | J8: Implemented by ApiResponse, API behavior configuration and GlobalExceptionMiddleware. | K8: Done
A9: US-008 | B9: Library | C9: User | D9: Library owner | E9: rename my library | F9: I can keep library information current | G9: • Owner can update the library name • Invalid names are rejected • Unauthorized users cannot update it | H9: Must Have | I9: M1 — Core Library | J9: Implemented by PATCH /api/libraries/{libraryId} with owner/editor authorization. | K9: In Progress
A10: US-009 | B10: Library | C10: User | D10: Authenticated user | E10: create a personal library | F10: I can start cataloguing my own collection | G10: • An authenticated user can create a library with a valid name • Private visibility is used when no visibility is supplied • The creator is recorded as the Owner member | H10: Must Have | I10: M1 — Core Library | J10: Implemented by POST /api/libraries with creator ownership. | K10: In Progress
A11: US-010 | B11: Library membership | C11: User | D11: Library member | E11: access only libraries I am authorized to use | F11: other users cannot view or change my collection | G11: • Membership is checked on library-scoped requests • Non-members cannot read or modify protected data • Owner role is recorded for the creator | H11: Must Have | I11: M1 — Core Library | J11: Implemented by library membership checks and owner/editor/viewer enforcement. | K11: Done
A12: US-011 | B12: Catalogue | C12: User | D12: Catalogue editor | E12: create an author record | F12: books can be associated with their authors | G12: • Author name is required • Optional biographical fields can be omitted • Saved author is available for book association | H12: Must Have | I12: M1 — Core Library | J12: Implemented by POST /api/authors. | K12: In Progress
... A27: US-026 | B27: Duplicate detection | C27: User | D27: Library member | E27: be warned if I already own the exact edition | F27: I can avoid accidental duplicate purchases | G27: • ISBN resolves to the edition • Ownership check is scoped to the selected library • Response indicates exact-edition ownership and number of copies | H27: Must Have | I27: M2 — Smart ISBN | J27: Implemented by library-scoped exact-edition ownership checks with copy count. | K27: In Progress
A28: US-027 | B28: Duplicate detection | C28: User | D28: Library member | E28: know if I own a different edition of the same book | F28: I can decide whether I still want another edition | G28: • Other editions are matched through their BookId • Response distinguishes other-edition ownership from exact match • Owned edition details are available | H28: Must Have | I28: M2 — Smart ISBN | K28: Not Started
A29: US-028 | B29: Duplicate detection | C29: User | D29: Library member | E29: see when a book is not owned | F29: I can add it confidently | G29: • No matching library copy returns not-owned status • An edition existing globally is not treated as owned • Result does not expose other libraries’ contents | H29: Must Have | I29: M2 — Smart ISBN | J29: Implemented by a library-scoped not-owned result without exposing other libraries. | K29: In Progress
A30: US-029 | B30: ISBN import | C30: User | D30: Library member with edit access | E30: confirm an ISBN lookup and add that edition to my library | F30: the identified book becomes part of my collection | G30: • Existing catalogue entities are reused • Missing book/edition entities are created when needed • One new BookCopy is created only after confirmation • Failure does not leave a partially imported copy | H30: Must Have | I30: M2 — Smart ISBN | J30: Backend implemented by POST /api/libraries/{libraryId}/book-imports/{isbn}, which resolves catalogue data and creates the copy transactionally. The mobile confirmation flow is still required. | K30: In Progress
A31: US-030 | B31: ISBN import | C31: User | D31: Library member | E31: manually complete a book when ISBN lookup fails | F31: books absent from metadata providers can still be catalogued | G31: • No-result response offers manual entry • Manual entry accepts required fields and optional edition data • User can save a copy without an ISBN | H31: Must Have | I31: M2 — Smart ISBN | J31: Manual catalogue and copy APIs support ISBN-free records. The mobile app still needs to detect the final no-result outcome and guide the user through manual entry. | K31: In Progress
A32: US-031 | B32: Mobile app | C32: User | D32: New user | E32: register from the mobile app | F32: I can create an account on my phone | G32: • Registration form validates inputs • API errors are displayed • Success proceeds to email confirmation/login | H32: Must Have | I32: M3 — Mobile MVP | K32: Not Started
A33: US-032 | B33: Mobile app | C33: User | D33: Registered user | E33: log in from the mobile app | F33: I can access my collections on my phone | G33: • Login form calls the API • Authenticated state is maintained appropriately • Invalid credentials show an error | H33: Must Have | I33: M3 — Mobile MVP | K33: Not Started
A34: US-033 | B34: Mobile app | C34: User | D34: Authenticated user | E34: see a home screen with my libraries | F34: I can quickly enter a collection | G34: • Home lists accessible libraries • User can select a library • Empty state supports creating a library | H34: Must Have | I34: M3 — Mobile MVP | K34: Not Started
A35: US-034 | B35: Mobile app | C35: User | D35: Library member | E35: browse my library on mobile | F35: I can see my owned books while away from home | G35: • Library screen lists copies/books • Selecting an item opens its details • Empty collection displays helpful guidance | H35: Must Have | I35: M3 — Mobile MVP | K35: Not Started
A36: US-035 | B36: Mobile app | C36: User | D36: Library member | E36: scan a book barcode with my phone | F36: I can identify a book without typing its ISBN | G36: • Camera permission is handled • Readable ISBN barcode is extracted • Detected ISBN starts lookup or allows confirmation | H36: Must Have | I36: M3 — Mobile MVP | K36: Not Started
A37: US-036 | B37: Mobile app | C37: User | D37: Library member | E37: review a book lookup result | F37: I can see metadata and ownership before saving | G37: • Lookup screen displays available metadata • Exact/other/not-owned state is shown • Add action is offered without forcing it | H37: Must Have | I37: M3 — Mobile MVP | K37: Not Started
A38: US-037 | B38: Mobile app | C38: User | D38: Library member | E38: view book and copy details | F38: I can inspect which edition I own | G38: • Book details show authors and edition • Copy-specific information is visible • Missing optional metadata is handled | H38: Must Have | I38: M3 — Mobile MVP | K38: Not Started
A39: US-038 | B39: Mobile app | C39: User | D39: Library member | E39: add a book from the mobile app | F39: I can finish cataloguing in one flow | G39: • User can confirm ISBN result or enter details manually • Selected library receives the new copy • Success and failure feedback are displayed | H39: Must Have | I39: M3 — Mobile MVP | K39: Not Started
A40: US-039 | B40: Search | C40: User | D40: Library member | E40: search my collection by title | F40: I can quickly find a book | G40: • Search is scoped to selected library • Partial title matches are supported • No-match state is returned | H40: Must Have | I40: M4 — Organization | J40: Library-content searchText supports title matching in the API. The mobile search experience is still required. | K40: In Progress
A41: US-040 | B41: Search | C41: User | D41: Library member | E41: search my collection by author | F41: I can find all my books by an author | G41: • Author-name matches are supported • Books with multiple authors are discoverable • Only accessible library results are returned | H41: Must Have | I41: M4 — Organization | K41: Not Started
A42: US-041 | B42: Search | C42: User | D42: Library member | E42: search my collection by ISBN | F42: I can locate a specific edition | G42: • ISBN is matched against edition identifiers • ISBN normalization is applied • Results are limited to selected library | H42: Must Have | I42: M4 — Organization | J42: Library-content searchText supports ISBN fields in the API. The mobile search experience is still required. | K42: In Progress
A43: US-042 | B43: Search | C43: User | D43: Library member | E43: filter my books by format and reading status | F43: I can focus on a subset of my collection | G43: • Format filter works • Reading-status filter works • Filters can be combined with search | H43: Must Have | I43: M4 — Organization | K43: Not Started
A44: US-043 | B44: Book copies | C44: User | D44: Library member with edit access | E44: update my copy’s reading status | F44: I can track my reading progress | G44: • Unread, Reading, Read, OnHold and Abandoned are supported • Change is saved to the specific copy • Other copies are unaffected | H44: Must Have | I44: M4 — Organization | K44: Not Started
A45: US-044 | B45: Locations | C45: User | D45: Library member with edit access | E45: create and assign library locations | F45: I can remember where books are stored | G45: • Location belongs to one library • Copy can reference an optional location • Parent/child locations are supported by the model | H45: Must Have | I45: M4 — Organization | J45: Location hierarchy and copy assignment exist in the model, but location management endpoints are missing. | K45: In Progress
A46: US-045 | B46: Book copies | C46: User | D46: Library member with edit access | E46: edit the details of an owned copy | F46: I can keep format, condition and notes accurate | G46: • Format, reading status, condition, acquisition date, purchase price/currency, signed/favourite flags, location and notes can be updated • Edition identity is not silently changed • Unauthorized changes are rejected | H46: Must Have | I46: M4 — Organization | K46: Not Started
A47: US-046 | B47: Book copies | C47: User | D47: Library member with edit access | E47: remove a copy from my library | F47: I can reflect books I no longer own | G47: • Only targeted copy is removed • Other copies of the edition remain • Catalogue book/edition is not deleted as a side effect | H47: Must Have | I47: M4 — Organization | K47: Not Started
A48: US-047 | B48: Search | C48: User | D48: Library member | E48: browse a large library in pages | F48: the list remains manageable | G48: • API accepts pagination parameters • Response includes page information • Filtering and pagination work together | H48: Must Have | I48: M4 — Organization | J48: The library-content API supports pageNumber, pageSize, searchText, orderBy and orderDirection. Mobile paging and filtering controls are still required. | K48: In Progress
A49: US-048 | B49: Bulk import | C49: User | D49: Library member | E49: scan multiple ISBNs in one session | F49: I can catalogue a large collection quickly | G49: • Multiple scans are collected into a batch • Items are visible before final import • Scanning can continue without individual confirmation | H49: Could Have | I49: M5 — Bulk Import | K49: Not Started
A50: US-049 | B50: Bulk import | C50: User | D50: Library member | E50: review a batch before importing | F50: I can catch mistakes and duplicates | G50: • Batch lists found, duplicate and failed items • User can exclude an item • Confirmed batch is submitted for processing | H50: Could Have | I50: M5 — Bulk Import | K50: Not Started
A51: US-050 | B51: Bulk import | C51: User | D51: Library member | E51: import many editions as a batch | F51: I can avoid repeating the add process | G51: • Import batch and item records are persisted • Each item has a processing outcome • Successful items create copies in selected library | H51: Could Have | I51: M5 — Bulk Import | K51: Not Started
A52: US-051 | B52: Bulk import | C52: User | D52: Library member | E52: process large imports in the background | F52: the app stays responsive during import | G52: • Processing does not require an open request • Batch status can be queried • Individual item errors do not halt unrelated items | H52: Could Have | I52: M5 — Bulk Import | K52: Not Started
A53: US-052 | B53: Bulk import | C53: User | D53: Library member | E53: see a duplicate and failure summary after import | F53: I know which books need attention | G53: • Counts of imported, duplicate and failed items are shown • Failures include actionable reasons • Failed items can be reviewed | H53: Could Have | I53: M5 — Bulk Import | K53: Not Started
A54: US-053 | B54: Reliability | C54: User | D54: Library member | E54: receive timely responses when a metadata provider is slow | F54: a failed service does not freeze my lookup | G54: • External requests have timeouts • Transient errors use bounded retries • Exhausted providers return a controlled error | H54: Should Have | I54: M6 — Production | J54: Provider timeouts and fallback exist; bounded retry policies are not implemented. | K54: In Progress
...

Sheet Overview
A1: PERSONAL LIBRARY MANAGER | USER STORY BACKLOG
A3: Metric | B3: Value
A4: Total stories | B4: =COUNTA('User Stories'!A2:A200) -> 85
A5: Must Have | B5: =COUNTIF('User Stories'!H2:H200,"Must Have") -> 49
A6: Should Have | B6: =COUNTIF('User Stories'!H2:H200,"Should Have") -> 16
A7: Could Have | B7: =COUNTIF('User Stories'!H2:H200,"Could Have") -> 20
A8: Completed | B8: =COUNTIF('User Stories'!K2:K200,"Done") -> 7
A9: In progress | B9: =COUNTIF('User Stories'!K2:K200,"In Progress") -> 41
A10: Milestone | B10: Stories | C10: Focus | D10: Phase
A11: M0 — Foundation | B11: =COUNTIF('User Stories'!I2:I200,"M0 — Foundation") -> 7 | C11: Identity & authentication | D11: MVP
A12: M1 — Core Library | B12: =COUNTIF('User Stories'!I2:I200,"M1 — Core Library") -> 19 | C12: Libraries, catalogue, manual add | D12: MVP
A13: M2 — Smart ISBN | B13: =COUNTIF('User Stories'!I2:I200,"M2 — Smart ISBN") -> 13 | C13: Lookup, metadata, duplicate detection | D13: MVP
A14: M3 — Mobile MVP | B14: =COUNTIF('User Stories'!I2:I200,"M3 — Mobile MVP") -> 8 | C14: MAUI screens and scan workflow | D14: MVP
A15: M4 — Organization | B15: =COUNTIF('User Stories'!I2:I200,"M4 — Organization") -> 10 | C15: Search, status, locations, edits | D15: Later
A16: M5 — Bulk Import | B16: =COUNTIF('User Stories'!I2:I200,"M5 — Bulk Import") -> 5 | C16: Batch scanning and import | D16: Later
A17: M6 — Production | B17: =COUNTIF('User Stories'!I2:I200,"M6 — Production") -> 9 | C17: Reliability, tests, deployment | D17: Later
A18: M7 — Social | B18: =COUNTIF('User Stories'!I2:I200,"M7 — Social") -> 9 | C18: Shared libraries, loans, wishlist | D18: Later
A19: Future | B19: =COUNTIF('User Stories'!I2:I200,"Future") -> 5 | C19: OCR, offline, notifications | D19: Later
A22: Notes
A23: Status and implementation evidence were reviewed on 27 October 2026.
A24: Story status is end-to-end. Backend, database and frontend progress is tracked separately on Tasks.
A25: M0–M3 are the MVP path. M4–M7 and Future remain subsequent work.
A27: Sources: Requirements, Product Vision, Milestones, Backlog, ERD, metadata-provider documentation, README and current repository implementation.

Sheet Epics
A1: Epic ID | B1: Epic | C1: Outcome | D1: Milestones | E1: Related US IDs | F1: Story Count | G1: Task Count | H1: Done Tasks | I1: In Progress | J1: Blocked | K1: Not Started | L1: Epic Status | M1: Sources and notes
A2: EP-001 | B2: Account and access | C2: Users can create, verify and securely use an account. | D2: M0 — Foundation | E2: US-001, US-002, US-003, US-004, US-005, US-006, US-007 | F2: 7 | G2: =COUNTIF(Tasks!$B$2:$B$298,A2) -> 26 | H2: =COUNTIFS(Tasks!$B$2:$B$298,A2,Tasks!$I$2:$I$298,"Done") -> 13 | I2: =COUNTIFS(Tasks!$B$2:$B$298,A2,Tasks!$I$2:$I$298,"In Progress") -> 3 | J2: =COUNTIFS(Tasks!$B$2:$B$298,A2,Tasks!$I$2:$I$298,"Blocked") -> 0 | K2: =COUNTIFS(Tasks!$B$2:$B$298,A2,Tasks!$I$2:$I$298,"Not Started") -> 10 | L2: =IF(J2>0,"Blocked",IF(H2=G2,"Done",IF(H2+I2>0,"In Progress","Not Started"))) -> In Progress | M2: Requirements.md: Account; Milestones.md: M0 Foundation
A3: EP-002 | B3: Libraries and membership | C3: Users can create, discover and securely manage libraries and membership. | D3: M1 — Core Library | E3: US-008, US-009, US-010, US-073, US-074 | F3: 5 | G3: =COUNTIF(Tasks!$B$2:$B$298,A3) -> 19 | H3: =COUNTIFS(Tasks!$B$2:$B$298,A3,Tasks!$I$2:$I$298,"Done") -> 9 | I3: =COUNTIFS(Tasks!$B$2:$B$298,A3,Tasks!$I$2:$I$298,"In Progress") -> 3 | J3: =COUNTIFS(Tasks!$B$2:$B$298,A3,Tasks!$I$2:$I$298,"Blocked") -> 0 | K3: =COUNTIFS(Tasks!$B$2:$B$298,A3,Tasks!$I$2:$I$298,"Not Started") -> 7 | L3: =IF(J3>0,"Blocked",IF(H3=G3,"Done",IF(H3+I3>0,"In Progress","Not Started"))) -> In Progress | M3: Requirements.md: Library; Milestones.md: M1; ERD.pdf
A4: EP-003 | B4: Catalogue management | C4: Catalogue users can manage and navigate books, authors, publishers and editions. | D4: M1 — Core Library; M4 — Organization | E4: US-011, US-012, US-013, US-014, US-015, US-016, US-075, US-076, US-077, US-078, US-079, US-082 | F4: 12 | G4: =COUNTIF(Tasks!$B$2:$B$298,A4) -> 46 | H4: =COUNTIFS(Tasks!$B$2:$B$298,A4,Tasks!$I$2:$I$298,"Done") -> 22 | I4: =COUNTIFS(Tasks!$B$2:$B$298,A4,Tasks!$I$2:$I$298,"In Progress") -> 0 | J4: =COUNTIFS(Tasks!$B$2:$B$298,A4,Tasks!$I$2:$I$298,"Blocked") -> 0 | K4: =COUNTIFS(Tasks!$B$2:$B$298,A4,Tasks!$I$2:$I$298,"Not Started") -> 24 | L4: =IF(J4>0,"Blocked",IF(H4=G4,"Done",IF(H4+I4>0,"In Progress","Not Started"))) -> In Progress | M4: Requirements.md: Catalogue; Milestones.md: M1 and M4; ERD.pdf
A5: EP-004 | B5: Book-copy management | C5: Library members can add and maintain the physical copies they own. | D5: M1 — Core Library; M4 — Organization | E5: US-017, US-018, US-019, US-043, US-045, US-046 | F5: 6 | G5: =COUNTIF(Tasks!$B$2:$B$298,A5) -> 24 | H5: =COUNTIFS(Tasks!$B$2:$B$298,A5,Tasks!$I$2:$I$298,"Done") -> 6 | I5: =COUNTIFS(Tasks!$B$2:$B$298,A5,Tasks!$I$2:$I$298,"In Progress") -> 0 | J5: =COUNTIFS(Tasks!$B$2:$B$298,A5,Tasks!$I$2:$I$298,"Blocked") -> 0 | K5: =COUNTIFS(Tasks!$B$2:$B$298,A5,Tasks!$I$2:$I$298,"Not Started") -> 18 | L5: =IF(J5>0,"Blocked",IF(H5=G5,"Done",IF(H5+I5>0,"In Progress","Not Started"))) -> In Progress | M5: Requirements.md: Book copies; ProductVision.md; ERD.pdf
A6: EP-005 | B6: ISBN and metadata | C6: ISBN lookup identifies books, normalizes metadata and supports confirmed or manual import. | D6: M2 — Smart ISBN | E6: US-020, US-021, US-022, US-023, US-024, US-025, US-029, US-030, US-080, US-081 | F6: 10 | G6: =COUNTIF(Tasks!$B$2:$B$298,A6) -> 31 | H6: =COUNTIFS(Tasks!$B$2:$B$298,A6,Tasks!$I$2:$I$298,"Done") -> 18 | I6: =COUNTIFS(Tasks!$B$2:$B$298,A6,Tasks!$I$2:$I$298,"In Progress") -> 3 | J6: =COUNTIFS(Tasks!$B$2:$B$298,A6,Tasks!$I$2:$I$298,"Blocked") -> 0 | K6: =COUNTIFS(Tasks!$B$2:$B$298,A6,Tasks!$I$2:$I$298,"Not Started") -> 10 | L6: =IF(J6>0,"Blocked",IF(H6=G6,"Done",IF(H6+I6>0,"In Progress","Not Started"))) -> In Progress | M6: Requirements.md: ISBN lookup; Milestones.md: M2; BookMetadataProviders.md
A7: EP-006 | B7: Ownership detection | C7: Users can distinguish exact, other-edition and not-owned outcomes before adding a copy. | D7: M2 — Smart ISBN | E7: US-026, US-027, US-028 | F7: 3 | G7: =COUNTIF(Tasks!$B$2:$B$298,A7) -> 9 | H7: =COUNTIFS(Tasks!$B$2:$B$298,A7,Tasks!$I$2:$I$298,"Done") -> 2 | I7: =COUNTIFS(Tasks!$B$2:$B$298,A7,Tasks!$I$2:$I$298,"In Progress") -> 2 | J7: =COUNTIFS(Tasks!$B$2:$B$298,A7,Tasks!$I$2:$I$298,"Blocked") -> 0 | K7: =COUNTIFS(Tasks!$B$2:$B$298,A7,Tasks!$I$2:$I$298,"Not Started") -> 5 | L7: =IF(J7>0,"Blocked",IF(H7=G7,"Done",IF(H7+I7>0,"In Progress","Not Started"))) -> In Progress | M7: Requirements.md: Duplicate detection; Milestones.md: M2
A8: EP-007 | B8: Mobile experience | C8: The MAUI app exposes the core account, library, scanning and book workflows. | D8: M3 — Mobile MVP | E8: US-031, US-032, US-033, US-034, US-035, US-036, US-037, US-038 | F8: 8 | G8: =COUNTIF(Tasks!$B$2:$B$298,A8) -> 24 | H8: =COUNTIFS(Tasks!$B$2:$B$298,A8,Tasks!$I$2:$I$298,"Done") -> 0 | I8: =COUNTIFS(Tasks!$B$2:$B$298,A8,Tasks!$I$2:$I$298,"In Progress") -> 0 | J8: =COUNTIFS(Tasks!$B$2:$B$298,A8,Tasks!$I$2:$I$298,"Blocked") -> 0 | K8: =COUNTIFS(Tasks!$B$2:$B$298,A8,Tasks!$I$2:$I$298,"Not Started") -> 24 | L8: =IF(J8>0,"Blocked",IF(H8=G8,"Done",IF(H8+I8>0,"In Progress","Not Started"))) -> Not Started | M8: Milestones.md: M3 Mobile MVP; ProductVision.md
A9: EP-008 | B9: Search and organization | C9: Users can find, filter, locate and organize books in large libraries. | D9: M4 — Organization | E9: US-039, US-040, US-041, US-042, US-044, US-047 | F9: 6 | G9: =COUNTIF(Tasks!$B$2:$B$298,A9) -> 19 | H9: =COUNTIFS(Tasks!$B$2:$B$298,A9,Tasks!$I$2:$I$298,"Done") -> 4 | I9: =COUNTIFS(Tasks!$B$2:$B$298,A9,Tasks!$I$2:$I$298,"In Progress") -> 0 | J9: =COUNTIFS(Tasks!$B$2:$B$298,A9,Tasks!$I$2:$I$298,"Blocked") -> 0 | K9: =COUNTIFS(Tasks!$B$2:$B$298,A9,Tasks!$I$2:$I$298,"Not Started") -> 15 | L9: =IF(J9>0,"Blocked",IF(H9=G9,"Done",IF(H9+I9>0,"In Progress","Not Started"))) -> In Progress | M9: Requirements.md: Library browsing; Milestones.md: M4
A10: EP-009 | B10: Bulk import | C10: Users can review and process many scans without blocking the application. | D10: M5 — Bulk Import | E10: US-048, US-049, US-050, US-051, US-052 | F10: 5 | G10: =COUNTIF(Tasks!$B$2:$B$298,A10) -> 25 | H10: =COUNTIFS(Tasks!$B$2:$B$298,A10,Tasks!$I$2:$I$298,"Done") -> 0 | I10: =COUNTIFS(Tasks!$B$2:$B$298,A10,Tasks!$I$2:$I$298,"In Progress") -> 0 | J10: =COUNTIFS(Tasks!$B$2:$B$298,A10,Tasks!$I$2:$I$298,"Blocked") -> 0 | K10: =COUNTIFS(Tasks!$B$2:$B$298,A10,Tasks!$I$2:$I$298,"Not Started") -> 25 | L10: =IF(J10>0,"Blocked",IF(H10=G10,"Done",IF(H10+I10>0,"In Progress","Not Started"))) -> Not Started | M10: ProductVision.md: Bulk scanning; Milestones.md: M5
A11: EP-010 | B11: Production engineering | C11: The application is observable, resilient, tested and deployable. | D11: M6 — Production | E11: US-053, US-054, US-055, US-056, US-057, US-058, US-059, US-060, US-061 | F11: 9 | G11: =COUNTIF(Tasks!$B$2:$B$298,A11) -> 19 | H11: =COUNTIFS(Tasks!$B$2:$B$298,A11,Tasks!$I$2:$I$298,"Done") -> 1 | I11: =COUNTIFS(Tasks!$B$2:$B$298,A11,Tasks!$I$2:$I$298,"In Progress") -> 3 | J11: =COUNTIFS(Tasks!$B$2:$B$298,A11,Tasks!$I$2:$I$298,"Blocked") -> 0 | K11: =COUNTIFS(Tasks!$B$2:$B$298,A11,Tasks!$I$2:$I$298,"Not Started") -> 15 | L11: =IF(J11>0,"Blocked",IF(H11=G11,"Done",IF(H11+I11>0,"In Progress","Not Started"))) -> In Progress | M11: Milestones.md: M6; README.md: Production features and delivery
A12: EP-011 | B12: Sharing, loans and discovery | C12: Users can share libraries, lend books and optionally connect with other readers. | D12: M7 — Social | E12: US-062, US-063, US-064, US-065, US-066, US-067, US-068, US-069, US-085 | F12: 9 | G12: =COUNTIF(Tasks!$B$2:$B$298,A12) -> 36 | H12: =COUNTIFS(Tasks!$B$2:$B$298,A12,Tasks!$I$2:$I$298,"Done") -> 7 | I12: =COUNTIFS(Tasks!$B$2:$B$298,A12,Tasks!$I$2:$I$298,"In Progress") -> 2 | J12: =COUNTIFS(Tasks!$B$2:$B$298,A12,Tasks!$I$2:$I$298,"Blocked") -> 0 | K12: =COUNTIFS(Tasks!$B$2:$B$298,A12,Tasks!$I$2:$I$298,"Not Started") -> 27 | L12: =IF(J12>0,"Blocked",IF(H12=G12,"Done",IF(H12+I12>0,"In Progress","Not Started"))) -> In Progress | M12: ProductVision.md: Shared libraries and lending; Milestones.md: M7; ERD.pdf
A13: EP-012 | B13: Future intelligence and offline | C13: The product can recognize books in new ways, work offline and provide useful insights. | D13: Future | E13: US-070, US-071, US-072, US-083, US-084 | F13: 5 | G13: =COUNTIF(Tasks!$B$2:$B$298,A13) -> 19 | H13: =COUNTIFS(Tasks!$B$2:$B$298,A13,Tasks!$I$2:$I$298,"Done") -> 0 | I13: =COUNTIFS(Tasks!$B$2:$B$298,A13,Tasks!$I$2:$I$298,"In Progress") -> 0 | J13: =COUNTIFS(Tasks!$B$2:$B$298,A13,Tasks!$I$2:$I$298,"Blocked") -> 0 | K13: =COUNTIFS(Tasks!$B$2:$B$298,A13,Tasks!$I$2:$I$298,"Not Started") -> 19 | L13: =IF(J13>0,"Blocked",IF(H13=G13,"Done",IF(H13+I13>0,"In Progress","Not Started"))) -> Not Started | M13: Requirements.md: Later requirements; README.md: Future; ProductVision.md

Sheet Tasks
A1: Task ID | B1: Epic ID | C1: US ID | D1: Area | E1: Task | F1: Done Criteria | G1: Milestone | H1: Priority | I1: Status | J1: Depends On | K1: Evidence and notes
A2: TASK-001-DB | B2: EP-001 | C2: US-001 | D2: Database | E2: Model and persist the data required to register with my email and password. | F2: Valid details create a user account Schema, relationships, constraints and migrations support the story safely. | G2: M0 — Foundation | H2: Must Have | I2: Done | K2: Implemented by registration validation, ASP.NET Core Identity and confirmation-email dispatch.
A3: TASK-001-BE | B3: EP-001 | C3: US-001 | D3: Backend/API | E3: Implement the API and application behavior to register with my email and password. | F3: Valid details create a user account Authorization, validation, success and failure responses are defined. | G3: M0 — Foundation | H3: Must Have | I3: Done | J3: TASK-001-DB | K3: Implemented by registration validation, ASP.NET Core Identity and confirmation-email dispatch.
A4: TASK-001-FE | B4: EP-001 | C4: US-001 | D4: Frontend | E4: Build the mobile user flow to register with my email and password. | F4: Valid details create a user account The user can complete the flow with loading, empty, validation and error states. | G4: M0 — Foundation | H4: Must Have | I4: Not Started | J4: TASK-001-BE | K4: The MAUI project does not yet provide this completed feature flow.
A5: TASK-001-TEST | B5: EP-001 | C5: US-001 | D5: Testing | E5: Automate acceptance coverage for the ability to register with my email and password. | F5: Valid details create a user account Happy paths, validation, authorization and failure paths are repeatable. | G5: M0 — Foundation | H5: Must Have | I5: In Progress | J5: TASK-001-DB, TASK-001-BE, TASK-001-FE | K5: Current unit tests cover part of the story; end-to-end acceptance coverage remains.
A6: TASK-002-DB | B6: EP-001 | C6: US-002 | D6: Database | E6: Model and persist the data required to confirm my email address. | F6: Confirmation token is validated Schema, relationships, constraints and migrations support the story safely. | G6: M0 — Foundation | H6: Must Have | I6: Done | K6: Implemented by GET /api/auth/confirm-email and Identity email tokens.
A7: TASK-002-BE | B7: EP-001 | C7: US-002 | D7: Backend/API | E7: Implement the API and application behavior to confirm my email address. | F7: Confirmation token is validated Authorization, validation, success and failure responses are defined. | G7: M0 — Foundation | H7: Must Have | I7: Done | J7: TASK-002-DB | K7: Implemented by GET /api/auth/confirm-email and Identity email tokens.
A8: TASK-002-FE | B8: EP-001 | C8: US-002 | D8: Frontend | E8: Build the mobile user flow to confirm my email address. | F8: Confirmation token is validated The user can complete the flow with loading, empty, validation and error states. | G8: M0 — Foundation | H8: Must Have | I8: Not Started | J8: TASK-002-BE | K8: The MAUI project does not yet provide this completed feature flow.
A9: TASK-002-TEST | B9: EP-001 | C9: US-002 | D9: Testing | E9: Automate acceptance coverage for the ability to confirm my email address. | F9: Confirmation token is validated Happy paths, validation, authorization and failure paths are repeatable. | G9: M0 — Foundation | H9: Must Have | I9: Not Started | J9: TASK-002-DB, TASK-002-BE, TASK-002-FE | K9: No completed implementation is documented in the current repository audit.
A10: TASK-003-DB | B10: EP-001 | C10: US-003 | D10: Database | E10: Model and persist the data required to log in to my account. | F10: Valid credentials return authentication tokens Schema, relationships, constraints and migrations support the story safely. | G10: M0 — Foundation | H10: Must Have | I10: Done | K10: Implemented by POST /api/auth/login, JWT issuance and protected controllers.
A11: TASK-003-BE | B11: EP-001 | C11: US-003 | D11: Backend/API | E11: Implement the API and application behavior to log in to my account. | F11: Valid credentials return authentication tokens Authorization, validation, success and failure responses are defined. | G11: M0 — Foundation | H11: Must Have | I11: Done | J11: TASK-003-DB | K11: Implemented by POST /api/auth/login, JWT issuance and protected controllers.
A12: TASK-003-FE | B12: EP-001 | C12: US-003 | D12: Frontend | E12: Build the mobile user flow to log in to my account. | F12: Valid credentials return authentication tokens The user can complete the flow with loading, empty, validation and error states. | G12: M0 — Foundation | H12: Must Have | I12: Not Started | J12: TASK-003-BE | K12: The MAUI project does not yet provide this completed feature flow.
A13: TASK-003-TEST | B13: EP-001 | C13: US-003 | D13: Testing | E13: Automate acceptance coverage for the ability to log in to my account. | F13: Valid credentials return authentication tokens Happy paths, validation, authorization and failure paths are repeatable. | G13: M0 — Foundation | H13: Must Have | I13: In Progress | J13: TASK-003-DB, TASK-003-BE, TASK-003-FE | K13: Current unit tests cover part of the story; end-to-end acceptance coverage remains.
A14: TASK-004-DB | B14: EP-001 | C14: US-004 | D14: Database | E14: Model and persist the data required to refresh an expired access token. | F14: Valid refresh token issues new authentication tokens Schema, relationships, constraints and migrations support the story safely. | G14: M0 — Foundation | H14: Must Have | I14: Done | K14: Implemented by POST /api/auth/refresh with refresh-token rotation and revocation.
A15: TASK-004-BE | B15: EP-001 | C15: US-004 | D15: Backend/API | E15: Implement the API and application behavior to refresh an expired access token. | F15: Valid refresh token issues new authentication tokens Authorization, validation, success and failure responses are defined. | G15: M0 — Foundation | H15: Must Have | I15: Done | J15: TASK-004-DB | K15: Implemented by POST /api/auth/refresh with refresh-token rotation and revocation.
A16: TASK-004-FE | B16: EP-001 | C16: US-004 | D16: Frontend | E16: Build the mobile user flow to refresh an expired access token. | F16: Valid refresh token issues new authentication tokens The user can complete the flow with loading, empty, validation and error states. | G16: M0 — Foundation | H16: Must Have | I16: Not Started | J16: TASK-004-BE | K16: The MAUI project does not yet provide this completed feature flow.
A17: TASK-004-TEST | B17: EP-001 | C17: US-004 | D17: Testing | E17: Automate acceptance coverage for the ability to refresh an expired access token. | F17: Valid refresh token issues new authentication tokens Happy paths, validation, authorization and failure paths are repeatable. | G17: M0 — Foundation | H17: Must Have | I17: Not Started | J17: TASK-004-DB, TASK-004-BE, TASK-004-FE | K17: No completed implementation is documented in the current repository audit.
A18: TASK-005-DB | B18: EP-001 | C18: US-005 | D18: Database | E18: Model and persist the data required to request a new email-confirmation message. | F18: An unconfirmed account receives a new confirmation challenge Schema, relationships, constraints and migrations support the story safely. | G18: M0 — Foundation | H18: Must Have | I18: Done | K18: Implemented by POST /api/auth/resend-confirmation and AuthService.
A19: TASK-005-BE | B19: EP-001 | C19: US-005 | D19: Backend/API | E19: Implement the API and application behavior to request a new email-confirmation message. | F19: An unconfirmed account receives a new confirmation challenge Authorization, validation, success and failure responses are defined. | G19: M0 — Foundation | H19: Must Have | I19: Done | J19: TASK-005-DB | K19: Implemented by POST /api/auth/resend-confirmation and AuthService.
A20: TASK-005-FE | B20: EP-001 | C20: US-005 | D20: Frontend | E20: Build the mobile user flow to request a new email-confirmation message. | F20: An unconfirmed account receives a new confirmation challenge The user can complete the flow with loading, empty, validation and error states. | G20: M0 — Foundation | H20: Must Have | I20: Not Started | J20: TASK-005-BE | K20: The MAUI project does not yet provide this completed feature flow.
A21: TASK-005-TEST | B21: EP-001 | C21: US-005 | D21: Testing | E21: Automate acceptance coverage for the ability to request a new email-confirmation message. | F21: An unconfirmed account receives a new confirmation challenge Happy paths, validation, authorization and failure paths are repeatable. | G21: M0 — Foundation | H21: Must Have | I21: Not Started | J21: TASK-005-DB, TASK-005-BE, TASK-005-FE | K21: No completed implementation is documented in the current repository audit.
A22: TASK-006-DB | B22: EP-001 | C22: US-006 | D22: Database | E22: Model and persist the data required to log out of my current refresh-token session. | F22: Logout requires an authenticated user Schema, relationships, constraints and migrations support the story safely. | G22: M0 — Foundation | H22: Must Have | I22: Done | K22: Implemented by POST /api/auth/logout with refresh-session revocation.
A23: TASK-006-BE | B23: EP-001 | C23: US-006 | D23: Backend/API | E23: Implement the API and application behavior to log out of my current refresh-token session. | F23: Logout requires an authenticated user Authorization, validation, success and failure responses are defined. | G23: M0 — Foundation | H23: Must Have | I23: Done | J23: TASK-006-DB | K23: Implemented by POST /api/auth/logout with refresh-session revocation.
A24: TASK-006-FE | B24: EP-001 | C24: US-006 | D24: Frontend | E24: Build the mobile user flow to log out of my current refresh-token session. | F24: Logout requires an authenticated user The user can complete the flow with loading, empty, validation and error states. | G24: M0 — Foundation | H24: Must Have | I24: Not Started | J24: TASK-006-BE | K24: The MAUI project does not yet provide this completed feature flow.
A25: TASK-006-TEST | B25: EP-001 | C25: US-006 | D25: Testing | E25: Automate acceptance coverage for the ability to log out of my current refresh-token session. | F25: Logout requires an authenticated user Happy paths, validation, authorization and failure paths are repeatable. | G25: M0 — Foundation | H25: Must Have | I25: In Progress | J25: TASK-006-DB, TASK-006-BE, TASK-006-FE | K25: Current unit tests cover part of the story; end-to-end acceptance coverage remains.
A26: TASK-007-BE | B26: EP-001 | C26: US-007 | D26: Backend/API | E26: Implement the API and application behavior to receive consistent success and failure responses. | F26: Successful responses use the common API envelope Authorization, validation, success and failure responses are defined. | G26: M0 — Foundation | H26: Should Have | I26: Done | K26: Implemented by ApiResponse, API behavior configuration and GlobalExceptionMiddleware.
A27: TASK-007-TEST | B27: EP-001 | C27: US-007 | D27: Testing | E27: Automate acceptance coverage for the ability to receive consistent success and failure responses. | F27: Successful responses use the common API envelope Happy paths, validation, authorization and failure paths are repeatable. | G27: M0 — Foundation | H27: Should Have | I27: Not Started | J27: TASK-007-BE | K27: No completed implementation is documented in the current repository audit.
A28: TASK-008-DB | B28: EP-002 | C28: US-008 | D28: Database | E28: Model and persist the data required to rename my library. | F28: Owner can update the library name Schema, relationships, constraints and migrations support the story safely. | G28: M1 — Core Library | H28: Must Have | I28: Done | K28: Implemented by PATCH /api/libraries/{libraryId} with owner/editor authorization.
A29: TASK-008-BE | B29: EP-002 | C29: US-008 | D29: Backend/API | E29: Implement the API and application behavior to rename my library. | F29: Owner can update the library name Authorization, validation, success and failure responses are defined. | G29: M1 — Core Library | H29: Must Have | I29: Done | J29: TASK-008-DB | K29: Implemented by PATCH /api/libraries/{libraryId} with owner/editor authorization.
A30: TASK-008-FE | B30: EP-002 | C30: US-008 | D30: Frontend | E30: Build the mobile user flow to rename my library. | F30: Owner can update the library name The user can complete the flow with loading, empty, validation and error states. | G30: M1 — Core Library | H30: Must Have | I30: Not Started | J30: TASK-008-BE | K30: The MAUI project does not yet provide this completed feature flow.
A31: TASK-008-TEST | B31: EP-002 | C31: US-008 | D31: Testing | E31: Automate acceptance coverage for the ability to rename my library. | F31: Owner can update the library name Happy paths, validation, authorization and failure paths are repeatable. | G31: M1 — Core Library | H31: Must Have | I31: In Progress | J31: TASK-008-DB, TASK-008-BE, TASK-008-FE | K31: Current unit tests cover part of the story; end-to-end acceptance coverage remains.
A32: TASK-009-DB | B32: EP-002 | C32: US-009 | D32: Database | E32: Model and persist the data required to create a personal library. | F32: An authenticated user can create a library with a valid name Schema, relationships, constraints and migrations support the story safely. | G32: M1 — Core Library | H32: Must Have | I32: Done | K32: Implemented by POST /api/libraries with creator ownership.
A33: TASK-009-BE | B33: EP-002 | C33: US-009 | D33: Backend/API | E33: Implement the API and application behavior to create a personal library. | F33: An authenticated user can create a library with a valid name Authorization, validation, success and failure responses are defined. | G33: M1 — Core Library | H33: Must Have | I33: Done | J33: TASK-009-DB | K33: Implemented by POST /api/libraries with creator ownership.
A34: TASK-009-FE | B34: EP-002 | C34: US-009 | D34: Frontend | E34: Build the mobile user flow to create a personal library. | F34: An authenticated user can create a library with a valid name The user can complete the flow with loading, empty, validation and error states. | G34: M1 — Core Library | H34: Must Have | I34: Not Started | J34: TASK-009-BE | K34: The MAUI project does not yet provide this completed feature flow.
A35: TASK-009-TEST | B35: EP-002 | C35: US-009 | D35: Testing | E35: Automate acceptance coverage for the ability to create a personal library. | F35: An authenticated user can create a library with a valid name Happy paths, validation, authorization and failure paths are repeatable. | G35: M1 — Core Library | H35: Must Have | I35: In Progress | J35: TASK-009-DB, TASK-009-BE, TASK-009-FE | K35: Current unit tests cover part of the story; end-to-end acceptance coverage remains.
A36: TASK-010-DB | B36: EP-002 | C36: US-010 | D36: Database | E36: Model and persist the data required to access only libraries I am authorized to use. | F36: Membership is checked on library-scoped requests Schema, relationships, constraints and migrations support the story safely. | G36: M1 — Core Library | H36: Must Have | I36: Done | K36: Implemented by library membership checks and owner/editor/viewer enforcement.
A37: TASK-010-BE | B37: EP-002 | C37: US-010 | D37: Backend/API | E37: Implement the API and application behavior to access only libraries I am authorized to use. | F37: Membership is checked on library-scoped requests Authorization, validation, success and failure responses are defined. | G37: M1 — Core Library | H37: Must Have | I37: Done | J37: TASK-010-DB | K37: Implemented by library membership checks and owner/editor/viewer enforcement.
A38: TASK-010-FE | B38: EP-002 | C38: US-010 | D38: Frontend | E38: Build the mobile user flow to access only libraries I am authorized to use. | F38: Membership is checked on library-scoped requests The user can complete the flow with loading, empty, validation and error states. | G38: M1 — Core Library | H38: Must Have | I38: Not Started | J38: TASK-010-BE | K38: The MAUI project does not yet provide this completed feature flow.
A39: TASK-010-TEST | B39: EP-002 | C39: US-010 | D39: Testing | E39: Automate acceptance coverage for the ability to access only libraries I am authorized to use. | F39: Membership is checked on library-scoped requests Happy paths, validation, authorization and failure paths are repeatable. | G39: M1 — Core Library | H39: Must Have | I39: Not Started | J39: TASK-010-DB, TASK-010-BE, TASK-010-FE | K39: No completed implementation is documented in the current repository audit.
A40: TASK-011-DB | B40: EP-003 | C40: US-011 | D40: Database | E40: Model and persist the data required to create an author record. | F40: Author name is required Schema, relationships, constraints and migrations support the story safely. | G40: M1 — Core Library | H40: Must Have | I40: Done | K40: Implemented by POST /api/authors.
...
